<mujoco model="furuta_pendulum">
    <compiler angle="radian"/>
    <option gravity="0 0 -9.81"/>

    <worldbody>
        <!-- Base -->
        <body name="base" pos="0 0 0">
            <joint name="base_joint" type="hinge" axis="0 0 1"/>
            <geom type="cylinder" size="0.05 0.1" rgba="0.2 0.2 0.2 1"/>
            
            <!-- Rotating Arm -->
            <body name="arm" pos="0 0 0.1">
                <joint name="arm_joint" type="hinge" axis="0 1 0"/>
                <geom type="capsule" fromto="0 0 0 0.3 0 0" size="0.02" rgba="0.2 0.5 0.8 1"/>
                
                <!-- Pendulum -->
                <body name="pendulum" pos="0.3 0 0">
                    <joint name="pendulum_joint" type="hinge" axis="1 0 0"/>
                    <geom type="capsule" fromto="0 0 0 0 -0.25 0" size="0.02" rgba="0.8 0.2 0.2 1"/>
                </body>
            </body>
        </body>
    </worldbody>

    <actuator>
        <motor joint="base_joint" ctrlrange="-2 2"/>
        <motor joint="arm_joint" ctrlrange="-2 2"/>
        <motor joint="pendulum_joint" ctrlrange="-2 2"/>
    </actuator>
</mujoco>
